Workbook

Sheet プロジェクト計画書
B1: 【注意】 | E1: グレーの網掛け部分は式が入っているので、入力しないでください。白い部分が入力項目です。
B2: 新規作成日 | K2: 新規作成者 | Q2: 更新日 | Y2: 更新者
B4: 顧客 | U4: プロジェクト区分 | Y4: Needs-in(顧客起点)
B5: プロジェクト名称
B6: プロジェクト概要 | G6: 人事制度改善支援
B11: 添付資料
G12: プロジェクトを通じて創出する価値・顧客満足は何か？
G13: お客様の現状問題の解決を向き合う人事制度の設計支援
G18: 価値に応じた収益が得られるか、コストは最適か？ | S18: 納期は最適か？
G19: ① 売上 | L19: =プロジェクト管理表!T24 -> 180000 | S19: プロジェクト開始予定日 | X19: 44287
G20: ② 経費 | L20: =プロジェクト管理表!T26 -> 0 | S20: プロジェクト終了予定日 | X20: 44530
G21: ③ 損益（①-②） | L21: =プロジェクト管理表!T28 -> 180000 | S21: プロジェクト期間 | X21: 8
G22: ④ 利益率（③/①） | L22: =プロジェクト管理表!T30 -> 1
G23: プロジェクトで行う問題解決は何か？
G24: ・現状人事状況の把握、問題認識 ・アドバイスを通じて、人事制度導入のサポート
G27: どのような経験・体験を通じて顧客満足を与えるか？
G28: 専門家によるサポートより、全面的な現状分析及び効率的な制度設計
G31: どのように人材・時間を投入するか？ | S31: プロジェクトを通じて組織・個人の能力はどのように向上するか？
G32: 役割 | J32: 氏名 | M32: クラス | O32: 工数 | S32: 沈： ・PJ管理。 ・BIツールの活用。 ・人事制度設計の全般を身に着ける。 王： ・BIツールの活用及び数字分析力の向上。 ・人事コンサル方法論を身に着ける。
G33: =プロジェクト管理表!C32 -> PPM | J33: =プロジェクト管理表!E32 -> 周娴 | M33: =プロジェクト管理表!E33 -> - | O33: =プロジェクト管理表!T32 -> 26
G34: =プロジェクト管理表!C34 -> PMO | J34: =プロジェクト管理表!E34 -> 0 | M34: =プロジェクト管理表!E35 -> - | O34: =プロジェクト管理表!T34 -> 0
G35: =プロジェクト管理表!C36 -> PD | J35: =プロジェクト管理表!E36 -> 山崎 | M35: =プロジェクト管理表!E37 -> - | O35: =プロジェクト管理表!T36 -> 0
G36: =プロジェクト管理表!C38 -> PM | J36: =プロジェクト管理表!E38 -> 沈庆元 | M36: =プロジェクト管理表!E39 -> - | O36: =プロジェクト管理表!T38 -> 96
G37: =プロジェクト管理表!C40 -> CREW① | J37: =プロジェクト管理表!E40 -> 王旭 | M37: =プロジェクト管理表!E41 -> - | O37: =プロジェクト管理表!T40 -> 96
G38: =プロジェクト管理表!C42 -> CREW② | J38: =プロジェクト管理表!E42 -> - | M38: =プロジェクト管理表!E43 -> - | O38: =プロジェクト管理表!T42 -> 0
G39: =プロジェクト管理表!C44 -> CREW③ | J39: =プロジェクト管理表!E44 -> - | M39: =プロジェクト管理表!E45 -> - | O39: =プロジェクト管理表!T44 -> 0 | S39: 組織的に広く活用できる方法論や知財が蓄積されるか？
G40: =プロジェクト管理表!C46 -> CREW④ | J40: =プロジェクト管理表!E46 -> - | M40: =プロジェクト管理表!E47 -> - | O40: =プロジェクト管理表!T46 -> 0 | S40: 組織力・生産性の向上
G41: =プロジェクト管理表!C48 -> CREW⑤ | J41: =プロジェクト管理表!E48 -> - | M41: =プロジェクト管理表!E49 -> - | O41: =プロジェクト管理表!T48 -> 0
G42: =プロジェクト管理表!C50 -> CREW⑥ | J42: =プロジェクト管理表!E50 -> - | M42: =プロジェクト管理表!E51 -> - | O42: =プロジェクト管理表!T50 -> 0
G43: 備考 | J43: ※工数は、プロジェクト期間の合計値
G44: 特記事項
B48: ■プロジェクト審査結果
B49: 審査結果 | L49: 特記事項
B50: 審査日
B51: 審査担当者
B53: プロジェクトID | G53: 001-P-21-079 | L53: プロジェクト フォルダ

Sheet プロジェクト管理表
B2: タスク | E2: 期間 | F2: 担当 | H2: =プロジェクト計画書!X19 -> 44287 | I2: =EDATE(H2,1) -> 44317 | J2: =EDATE(I2,1) -> 44348 | K2: =EDATE(J2,1) -> 44378 | L2: =EDATE(K2,1) -> 44409 | M2: =EDATE(L2,1) -> 44440 | N2: =EDATE(M2,1) -> 44470 | O2: =EDATE(N2,1) -> 44501 | P2: =EDATE(O2,1) -> 44531 | ... S2: =EDATE(R2,1) -> 44621 | T2: 備考
B3: 資料確認・現状分析 | E3: 84 | F3: 沈
B5: 報告作成・中間報告 | E5: 22 | F5: 沈
B7: 報告修正・最終報告 | E7: 24 | F7: 沈
B9: 等級制度のアドバイス | E9: 28 | F9: 沈
B11: 報酬制度のアドバイス | E11: 26 | F11: 沈
B13: 評価制度のアドバイス | E13: 28 | F13: 沈
B23: プロジェクト期間 | H23: =プロジェクト計画書!X19 -> 44287 | I23: =EDATE(H23,1) -> 44317 | J23: =EDATE(I23,1) -> 44348 | K23: =EDATE(J23,1) -> 44378 | L23: =EDATE(K23,1) -> 44409 | M23: =EDATE(L23,1) -> 44440 | N23: =EDATE(M23,1) -> 44470 | O23: =EDATE(N23,1) -> 44501 | P23: =EDATE(O23,1) -> 44531 | ... S23: =EDATE(R23,1) -> 44621 | T23: 合計
B24: 収支 | C24: ①売上 | F24: 計画 | H24: 33000 | I24: 33000 | J24: 34000 | K24: 16000 | L24: 16000 | M24: 16000 | N24: 16000 | O24: 16000 | T24: =SUM(H24:S24) -> 180000
F25: 実績 | T25: =SUM(H25:S25) -> 0
C26: ②経費 | F26: 計画 | H26: =$G$32*H32+$G$38*H38+$G$40*H40+$G$42*H42+$G$44*H44+$G$46*H46+$G$48*H48+$G$50*H50 -> 0 | I26: =$G$32*I32+$G$38*I38+$G$40*I40+$G$42*I42+$G$44*I44+$G$46*I46+$G$48*I48+$G$50*I50 -> 0 | J26: =$G$32*J32+$G$38*J38+$G$40*J40+$G$42*J42+$G$44*J44+$G$46*J46+$G$48*J48+$G$50*J50 -> 0 | K26: =$G$32*K32+$G$38*K38+$G$40*K40+$G$42*K42+$G$44*K44+$G$46*K46+$G$48*K48+$G$50*K50 -> 0 | L26: =$G$32*L32+$G$38*L38+$G$40*L40+$G$42*L42+$G$44*L44+$G$46*L46+$G$48*L48+$G$50*L50 -> 0 | M26: =$G$32*M32+$G$38*M38+$G$40*M40+$G$42*M42+$G$44*M44+$G$46*M46+$G$48*M48+$G$50*M50 -> 0 | N26: =$G$32*N32+$G$38*N38+$G$40*N40+$G$42*N42+$G$44*N44+$G$46*N46+$G$48*N48+$G$50*N50 -> 0 | O26: =$G$32*O32+$G$38*O38+$G$40*O40+$G$42*O42+$G$44*O44+$G$46*O46+$G$48*O48+$G$50*O50 -> 0 | ... S26: =$G$32*S32+$G$38*S38+$G$40*S40+$G$42*S42+$G$44*S44+$G$46*S46+$G$48*S48+$G$50*S50 -> 0 | T26: =SUM(H26:S26) -> 0
F27: 実績 | H27: =$G$33*H33+$G$39*H39+$G$41*H41+$G$43*H43+$G$45*H45+$G$47*H47+$G$49*H49+$G$51*H51 -> 0 | I27: =$G$33*I33+$G$39*I39+$G$41*I41+$G$43*I43+$G$45*I45+$G$47*I47+$G$49*I49+$G$51*I51 -> 0 | J27: =$G$33*J33+$G$39*J39+$G$41*J41+$G$43*J43+$G$45*J45+$G$47*J47+$G$49*J49+$G$51*J51 -> 0 | K27: =$G$33*K33+$G$39*K39+$G$41*K41+$G$43*K43+$G$45*K45+$G$47*K47+$G$49*K49+$G$51*K51 -> 0 | L27: =$G$33*L33+$G$39*L39+$G$41*L41+$G$43*L43+$G$45*L45+$G$47*L47+$G$49*L49+$G$51*L51 -> 0 | M27: =$G$33*M33+$G$39*M39+$G$41*M41+$G$43*M43+$G$45*M45+$G$47*M47+$G$49*M49+$G$51*M51 -> 0 | N27: =$G$33*N33+$G$39*N39+$G$41*N41+$G$43*N43+$G$45*N45+$G$47*N47+$G$49*N49+$G$51*N51 -> 0 | O27: =$G$33*O33+$G$39*O39+$G$41*O41+$G$43*O43+$G$45*O45+$G$47*O47+$G$49*O49+$G$51*O51 -> 0 | ... S27: =$G$33*S33+$G$39*S39+$G$41*S41+$G$43*S43+$G$45*S45+$G$47*S47+$G$49*S49+$G$51*S51 -> 0 | T27: =SUM(H27:S27) -> 0
C28: ③損益 | D28: （①－②） | F28: 計画 | H28: =H24-H26 -> 33000 | I28: =I24-I26 -> 33000 | J28: =J24-J26 -> 34000 | K28: =K24-K26 -> 16000 | L28: =L24-L26 -> 16000 | M28: =M24-M26 -> 16000 | N28: =N24-N26 -> 16000 | O28: =O24-O26 -> 16000 | ... S28: =S24-S26 -> 0 | T28: =SUM(H28:S28) -> 180000
F29: 実績 | H29: =H25-H27 -> 0 | I29: =I25-I27 -> 0 | J29: =J25-J27 -> 0 | K29: =K25-K27 -> 0 | L29: =L25-L27 -> 0 | M29: =M25-M27 -> 0 | N29: =N25-N27 -> 0 | O29: =O25-O27 -> 0 | ... S29: =S25-S27 -> 0 | T29: =SUM(H29:S29) -> 0
C30: ④損益率 | D30: （③/①） | F30: 計画 | H30: =H28/H24 -> 1 | I30: =I28/I24 -> 1 | J30: =J28/J24 -> 1 | K30: =K28/K24 -> 1 | L30: =L28/L24 -> 1 | M30: =M28/M24 -> 1 | N30: =N28/N24 -> 1 | O30: =O28/O24 -> 1 | ... T30: =T28/T24 -> 1
F31: 実績 | H31: =H29/H25 -> #DIV/0! | I31: =I29/I25 -> #DIV/0! | J31: =J29/J25 -> #DIV/0! | K31: =K29/K25 -> #DIV/0! | L31: =L29/L25 -> #DIV/0! | M31: =M29/M25 -> #DIV/0! | N31: =N29/N25 -> #DIV/0! | O31: =O29/O25 -> #DIV/0! | ... T31: =T29/T25 -> #DIV/0!
B32: 工数 | C32: PPM | D32: 氏名 | E32: 周娴 | F32: 計画 | H32: 4 | I32: 6 | J32: 2 | K32: 4 | L32: 2 | M32: 2 | N32: 2 | O32: 4 | T32: =SUM(H32:S32) -> 26
D33: クラス | E33: - | F33: 実績 | T33: =SUM(H33:S33) -> 0
C34: PMO | D34: 氏名 | F34: 計画 | T34: =SUM(H34:S34) -> 0
D35: クラス | E35: - | F35: 実績 | T35: =SUM(H35:S35) -> 0
C36: PD | D36: 氏名 | E36: 山崎 | F36: 計画 | T36: =SUM(H36:S36) -> 0
D37: クラス | E37: - | F37: 実績 | T37: =SUM(H37:S37) -> 0
C38: PM | D38: 氏名 | E38: 沈庆元 | F38: 計画 | H38: 40 | I38: 20 | J38: 4 | K38: 8 | L38: 4 | M38: 8 | N38: 4 | O38: 8 | T38: =SUM(H38:S38) -> 96
D39: クラス | E39: - | F39: 実績 | T39: =SUM(H39:S39) -> 0
C40: CREW① | D40: 氏名 | E40: 王旭 | F40: 計画 | H40: 40 | I40: 20 | J40: 4 | K40: 8 | L40: 4 | M40: 8 | N40: 4 | O40: 8 | T40: =SUM(H40:S40) -> 96
D41: クラス | E41: - | F41: 実績 | T41: =SUM(H41:S41) -> 0
C42: CREW② | D42: 氏名 | E42: - | F42: 計画 | T42: =SUM(H42:S42) -> 0
D43: クラス | E43: - | F43: 実績 | T43: =SUM(H43:S43) -> 0
C44: CREW③ | D44: 氏名 | E44: - | F44: 計画 | T44: =SUM(H44:S44) -> 0
D45: クラス | E45: - | F45: 実績 | T45: =SUM(H45:S45) -> 0
C46: CREW④ | D46: 氏名 | E46: - | F46: 計画 | T46: =SUM(H46:S46) -> 0
D47: クラス | E47: - | F47: 実績 | T47: =SUM(H47:S47) -> 0
C48: CREW⑤ | D48: 氏名 | E48: - | F48: 計画 | T48: =SUM(H48:S48) -> 0
D49: クラス | E49: - | F49: 実績 | T49: =SUM(H49:S49) -> 0
C50: CREW⑥ | D50: 氏名 | E50: - | F50: 計画 | T50: =SUM(H50:S50) -> 0
D51: クラス | E51: - | F51: 実績 | T51: =SUM(H51:S51) -> 0
B52: 備考

Sheet プロジェクト報告書
B1: 【注意】 | E1: グレーの網掛け部分は式が入っているので、入力しないでください。白い部分が入力項目です。
B2: 新規作成日 | K2: 新規作成者 | Q2: 更新日 | Y2: 更新者
B4: プロジェクト名称 | G4: =プロジェクト計画書!G4 -> 0 | U4: プロジェクト区分 | Y4: =プロジェクト計画書!Y4 -> Needs-in(顧客起点)
B5: 顧客・協力会社 | G5: =プロジェクト計画書!G5 -> 0
B6: プロジェクト概要 | G6: =プロジェクト計画書!G6 -> 人事制度改善支援
B11: 添付資料
G12: プロジェクトを通じて創出した価値・顧客満足は何か？
G18: 価値に応じた収益が得られたか、コストは最適だったか？ | S18: 納期は最適だったか？
G19: 項目 | L19: 予定 | O19: 実績 | S19: 項目 | X19: 予定 | AB19: 実績
G20: ①売上 | L20: =プロジェクト管理表!T24 -> 180000 | O20: =プロジェクト管理表!T25 -> 0 | S20: プロジェクト開始予定日 | X20: =プロジェクト計画書!X19 -> 44287
G21: ②経費 | L21: =プロジェクト管理表!T26 -> 0 | O21: =プロジェクト管理表!T27 -> 0 | S21: プロジェクト終了予定日 | X21: =プロジェクト計画書!X20 -> 44530
G22: ③損益（①-②） | L22: =プロジェクト管理表!T28 -> 180000 | O22: =プロジェクト管理表!T29 -> 0 | S22: プロジェクト期間 | X22: =プロジェクト計画書!X21 -> 8
G23: ④利益率（③/①） | L23: =プロジェクト管理表!T30 -> 1 | O23: =プロジェクト管理表!T31 -> #DIV/0!
G24: ①～④の「予定」と「実績」が異なった場合、原因は何か？ | S24: 納期の「予定」と「実績」が異なった場合、原因は何か？
G30: プロジェクトで行った問題解決は何か？
G34: どのような経験・体験を通じて顧客満足を与えたか？
G38: どのように人材・時間を投入するか？ | S38: 工数の「予定」と「実績」が異なった場合、原因は何か？
G39: 役割 | J39: 氏名 | M39: クラス | O39: 工数
O40: 予定 | Q40: 実績
G41: =プロジェクト管理表!C32 -> PPM | J41: =プロジェクト計画書!J33 -> 周娴 | M41: =プロジェクト計画書!M33 -> - | O41: =プロジェクト計画書!O33 -> 26 | Q41: =プロジェクト管理表!T33 -> 0
G42: =プロジェクト管理表!C34 -> PMO | J42: =プロジェクト計画書!J34 -> 0 | M42: =プロジェクト計画書!M34 -> - | O42: =プロジェクト計画書!O34 -> 0 | Q42: =プロジェクト管理表!T35 -> 0
G43: =プロジェクト管理表!C36 -> PD | J43: =プロジェクト計画書!J35 -> 山崎 | M43: =プロジェクト計画書!M35 -> - | O43: =プロジェクト計画書!O35 -> 0 | Q43: =プロジェクト管理表!T37 -> 0
G44: =プロジェクト管理表!C38 -> PM | J44: =プロジェクト計画書!J36 -> 沈庆元 | M44: =プロジェクト計画書!M36 -> - | O44: =プロジェクト計画書!O36 -> 96 | Q44: =プロジェクト管理表!T39 -> 0
G45: =プロジェクト管理表!C40 -> CREW① | J45: =プロジェクト計画書!J37 -> 王旭 | M45: =プロジェクト計画書!M37 -> - | O45: =プロジェクト計画書!O37 -> 96 | Q45: =プロジェクト管理表!T41 -> 0
G46: =プロジェクト管理表!C42 -> CREW② | J46: =プロジェクト計画書!J38 -> - | M46: =プロジェクト計画書!M38 -> - | O46: =プロジェクト計画書!O38 -> 0 | Q46: =プロジェクト管理表!T43 -> 0
G47: =プロジェクト管理表!C44 -> CREW③ | J47: =プロジェクト計画書!J39 -> - | M47: =プロジェクト計画書!M39 -> - | O47: =プロジェクト計画書!O39 -> 0 | Q47: =プロジェクト管理表!T45 -> 0
G48: =プロジェクト管理表!C46 -> CREW④ | J48: =プロジェクト計画書!J40 -> - | M48: =プロジェクト計画書!M40 -> - | O48: =プロジェクト計画書!O40 -> 0 | Q48: =プロジェクト管理表!T47 -> 0
G49: =プロジェクト管理表!C48 -> CREW⑤ | J49: =プロジェクト計画書!J41 -> - | M49: =プロジェクト計画書!M41 -> - | O49: =プロジェクト計画書!O41 -> 0 | Q49: =プロジェクト管理表!T49 -> 0
G50: =プロジェクト管理表!C50 -> CREW⑥ | J50: =プロジェクト計画書!J42 -> - | M50: =プロジェクト計画書!M42 -> - | O50: =プロジェクト計画書!O42 -> 0 | Q50: =プロジェクト管理表!T51 -> 0
G51: 備考 | J51: ※工数は、プロジェクト期間の合計値
G52: プロジェクトを通じて組織・個人の能力はどのように向上したか？
G57: 組織的に広く活用できる方法論や知財が蓄積されたか？
B62: プロジェクトの振り返り | G62: もっと良いプロジェクトにするには、どうしたらよかったか？次のプロジェクトで更に取り組みたいことは何か？
B72: ■プロジェクト評価
B73: 評価日 | J73: 評価者
B74: 総評 | C74: Q: C: D:
J79: ①5万元以下:1、5～15万元:3、15万元以上:5
B80: 役割 | E80: 氏名 | H80: クラス | J80: ① 基準点 | L80: ②QCD評価点 | N80: ③ 貢献点 | P80: ④ 調整係数 | R80: 評価 | T80: 評価
B82: =プロジェクト管理表!C32 -> PPM | E82: =J41 -> 周娴 | H82: =M41 -> - | R82: =(($J$82*$L$82)+N82)*P82 -> 0
B83: =プロジェクト管理表!C34 -> PMO | E83: =J42 -> 0 | H83: =M42 -> - | R83: =(($J$82*$L$82)+N83)*P83 -> 0
...
